Workbook
Name BreakEvenUnits: Financial_Model!$B$33
Name FixedCosts: Financial_Model!$B$29
Name Slicer_Category: #N/A
Name TotalProfit: Financial_Model!$D$5:$D$16
Name TotalRevenue: Financial_Model!$B$5:$B$16

Sheet Dashboard
A1: ENTERPRISE SALES PERFORMANCE & FINANCIAL ANALYTICS DASHBOARD
A3: FY2025 | All Regions | Data source: Sales_Data (300 transactions), Budget_Data
A5: TOTAL REVENUE | D5: TOTAL GROSS PROFIT | G5: AVG PROFIT MARGIN | J5: BUDGET VARIANCE
A6: =SUM(Financial_Model!B5:B16) -> 610434 | D6: =SUM(Financial_Model!D5:D16) -> 267284 | G6: =AVERAGE(Financial_Model!E5:E16) -> 44.333333 | J6: =SUM(Financial_Model!D21:D24) -> 684
A10: Monthly Revenue & Profit Trend | G10: Budget vs Actual by Department
A27: Month-over-Month Growth Rate % | G27: Break-even Snapshot (Laptop Pro 15)
G28: Break-even Units/Month | J28: =Financial_Model!B33 -> 100
G29: Break-even Revenue/Month | J29: =Financial_Model!B34 -> 120000
G30: Contribution Margin/Unit | J30: =Financial_Model!B32 -> 350

Sheet Executive_Summary
A1: EXECUTIVE SUMMARY — Enterprise Sales Performance & Financial Analytics
B4: 1. Overview
B5: • This report analyzes 300 sales transactions across 4 regions and 10 products for FY2025, alongside departmental budget performance across Sales, Marketing, Operations, and R&D.
B7: 2. Key Performance Indicators (live-linked to Dashboard)
B8: Total Revenue | D8: =Dashboard!A6 -> 610434
B9: Total Gross Profit | D9: =Dashboard!D6 -> 267284
B10: Average Profit Margin | D10: =Dashboard!G6 -> 44.333333
B11: Net Budget Variance | D11: =Dashboard!J6 -> 684
B13: 3. Business Insights
B14: • Revenue shows a clear seasonal pattern with peaks in July, November, and June, and the softest months in April, January, and February — worth planning inventory and sales campaigns around.
B15: • Profit margins are strongest in April and weakest in September, suggesting cost pressures or discounting varied significantly by month even as revenue grew.
B16: • Sales department finished the year under budget (favorable variance), while Marketing, Operations, and R&D all ran over budget — most notably Operations.
B17: • Break-even analysis for the flagship Laptop Pro 15 shows the product needs 129 units/month (~$154,800 revenue) to cover its allocated fixed overhead — a useful benchmark for monthly sales targets on this SKU.
B18: • The Electronics category (Laptop, Monitor, Mouse, Keyboard) likely drives the largest share of revenue given its higher unit prices — worth cross-checking against the Advanced_Functions sheet's high-value order filter.
B20: 4. Business Recommendations
B21: • Align inventory and staffing with the identified seasonal peaks (Mar/Jul/Nov) and plan promotions to smooth out the April/August dips.
B22: • Investigate the Operations budget overrun specifically — it shows both the largest dollar and percentage variance among all departments.
B23: • Use the break-even benchmark (129 units/month) as a minimum sales target for the Laptop Pro 15 in monthly sales reviews.
B24: • Extend this financial model with a rolling 3-month moving average (Forecast Sheet / Trend Analysis) to project Q1 2026 revenue for budget planning.
B25: • Standardize monthly Power Query refreshes as new branch data arrives, so this dashboard updates automatically instead of requiring manual data entry each month.
... B31: • XLOOKUP, UNIQUE, SORT and FILTER formulas (Advanced_Functions sheet) require Excel 365 or Excel 2021; an INDEX-MATCH equivalent is provided alongside each for backward compatibility.

Sheet Financial_Model
A1: FINANCIAL MODEL — Revenue, Profit, Budget vs Actual, Growth Rate, Break-even (formula-driven)
A3: 1. Monthly Revenue, Profit & Growth Rate
A4: Month | B4: Revenue | C4: COGS | D4: Gross Profit | E4: Profit Margin % | F4: Growth Rate % (MoM)
A5: Jan-2025 | B5: =SUMPRODUCT((MONTH(Sales_Data!$B$2:$B$301)=1)*(Sales_Data!$J$2:$J$301)) -> 29771 | C5: =SUMPRODUCT((MONTH(Sales_Data!$B$2:$B$301)=1)*(Sales_Data!$K$2:$K$301)) -> 15907 | D5: =B5-C5 -> 13864 | E5: =IFERROR(ROUND(D5/B5*100,1),0) -> 46.6 | F5: 0
A6: Feb-2025 | B6: =SUMPRODUCT((MONTH(Sales_Data!$B$2:$B$301)=2)*(Sales_Data!$J$2:$J$301)) -> 33061 | C6: =SUMPRODUCT((MONTH(Sales_Data!$B$2:$B$301)=2)*(Sales_Data!$K$2:$K$301)) -> 19892 | D6: =B6-C6 -> 13169 | E6: =IFERROR(ROUND(D6/B6*100,1),0) -> 39.8 | F6: =IFERROR(ROUND((B6-B5)/B5*100,1),0) -> 11.1
A7: Mar-2025 | B7: =SUMPRODUCT((MONTH(Sales_Data!$B$2:$B$301)=3)*(Sales_Data!$J$2:$J$301)) -> 61462 | C7: =SUMPRODUCT((MONTH(Sales_Data!$B$2:$B$301)=3)*(Sales_Data!$K$2:$K$301)) -> 35551 | D7: =B7-C7 -> 25911 | E7: =IFERROR(ROUND(D7/B7*100,1),0) -> 42.2 | F7: =IFERROR(ROUND((B7-B6)/B6*100,1),0) -> 85.9
A8: Apr-2025 | B8: =SUMPRODUCT((MONTH(Sales_Data!$B$2:$B$301)=4)*(Sales_Data!$J$2:$J$301)) -> 26088 | C8: =SUMPRODUCT((MONTH(Sales_Data!$B$2:$B$301)=4)*(Sales_Data!$K$2:$K$301)) -> 12243 | D8: =B8-C8 -> 13845 | E8: =IFERROR(ROUND(D8/B8*100,1),0) -> 53.1 | F8: =IFERROR(ROUND((B8-B7)/B7*100,1),0) -> -57.6
A9: May-2025 | B9: =SUMPRODUCT((MONTH(Sales_Data!$B$2:$B$301)=5)*(Sales_Data!$J$2:$J$301)) -> 45155 | C9: =SUMPRODUCT((MONTH(Sales_Data!$B$2:$B$301)=5)*(Sales_Data!$K$2:$K$301)) -> 23814 | D9: =B9-C9 -> 21341 | E9: =IFERROR(ROUND(D9/B9*100,1),0) -> 47.3 | F9: =IFERROR(ROUND((B9-B8)/B8*100,1),0) -> 73.1
A10: Jun-2025 | B10: =SUMPRODUCT((MONTH(Sales_Data!$B$2:$B$301)=6)*(Sales_Data!$J$2:$J$301)) -> 62980 | C10: =SUMPRODUCT((MONTH(Sales_Data!$B$2:$B$301)=6)*(Sales_Data!$K$2:$K$301)) -> 35269 | D10: =B10-C10 -> 27711 | E10: =IFERROR(ROUND(D10/B10*100,1),0) -> 44 | F10: =IFERROR(ROUND((B10-B9)/B9*100,1),0) -> 39.5
A11: Jul-2025 | B11: =SUMPRODUCT((MONTH(Sales_Data!$B$2:$B$301)=7)*(Sales_Data!$J$2:$J$301)) -> 93004 | C11: =SUMPRODUCT((MONTH(Sales_Data!$B$2:$B$301)=7)*(Sales_Data!$K$2:$K$301)) -> 51976 | D11: =B11-C11 -> 41028 | E11: =IFERROR(ROUND(D11/B11*100,1),0) -> 44.1 | F11: =IFERROR(ROUND((B11-B10)/B10*100,1),0) -> 47.7
A12: Aug-2025 | B12: =SUMPRODUCT((MONTH(Sales_Data!$B$2:$B$301)=8)*(Sales_Data!$J$2:$J$301)) -> 36426 | C12: =SUMPRODUCT((MONTH(Sales_Data!$B$2:$B$301)=8)*(Sales_Data!$K$2:$K$301)) -> 18678 | D12: =B12-C12 -> 17748 | E12: =IFERROR(ROUND(D12/B12*100,1),0) -> 48.7 | F12: =IFERROR(ROUND((B12-B11)/B11*100,1),0) -> -60.8
A13: Sep-2025 | B13: =SUMPRODUCT((MONTH(Sales_Data!$B$2:$B$301)=9)*(Sales_Data!$J$2:$J$301)) -> 43734 | C13: =SUMPRODUCT((MONTH(Sales_Data!$B$2:$B$301)=9)*(Sales_Data!$K$2:$K$301)) -> 26851 | D13: =B13-C13 -> 16883 | E13: =IFERROR(ROUND(D13/B13*100,1),0) -> 38.6 | F13: =IFERROR(ROUND((B13-B12)/B12*100,1),0) -> 20.1
A14: Oct-2025 | B14: =SUMPRODUCT((MONTH(Sales_Data!$B$2:$B$301)=10)*(Sales_Data!$J$2:$J$301)) -> 59486 | C14: =SUMPRODUCT((MONTH(Sales_Data!$B$2:$B$301)=10)*(Sales_Data!$K$2:$K$301)) -> 33859 | D14: =B14-C14 -> 25627 | E14: =IFERROR(ROUND(D14/B14*100,1),0) -> 43.1 | F14: =IFERROR(ROUND((B14-B13)/B13*100,1),0) -> 36
A15: Nov-2025 | B15: =SUMPRODUCT((MONTH(Sales_Data!$B$2:$B$301)=11)*(Sales_Data!$J$2:$J$301)) -> 71447 | C15: =SUMPRODUCT((MONTH(Sales_Data!$B$2:$B$301)=11)*(Sales_Data!$K$2:$K$301)) -> 41989 | D15: =B15-C15 -> 29458 | E15: =IFERROR(ROUND(D15/B15*100,1),0) -> 41.2 | F15: =IFERROR(ROUND((B15-B14)/B14*100,1),0) -> 20.1
A16: Dec-2025 | B16: =SUMPRODUCT((MONTH(Sales_Data!$B$2:$B$301)=12)*(Sales_Data!$J$2:$J$301)) -> 47820 | C16: =SUMPRODUCT((MONTH(Sales_Data!$B$2:$B$301)=12)*(Sales_Data!$K$2:$K$301)) -> 27121 | D16: =B16-C16 -> 20699 | E16: =IFERROR(ROUND(D16/B16*100,1),0) -> 43.3 | F16: =IFERROR(ROUND((B16-B15)/B15*100,1),0) -> -33.1
A19: 2. Budget vs Actual by Department (Annual)
A20: Department | B20: Budgeted | C20: Actual | D20: Variance | E20: Variance %
A21: Sales | B21: =SUMIFS(Budget_Data!C2:C49,Budget_Data!B2:B49,A21) -> 2172697 | C21: =SUMIFS(Budget_Data!D2:D49,Budget_Data!B2:B49,A21) -> 2111917 | D21: =C21-B21 -> -60780 | E21: =IFERROR(ROUND((C21-B21)/B21*100,1),0) -> -2.8
A22: Marketing | B22: =SUMIFS(Budget_Data!C2:C49,Budget_Data!B2:B49,A22) -> 1082927 | C22: =SUMIFS(Budget_Data!D2:D49,Budget_Data!B2:B49,A22) -> 1096696 | D22: =C22-B22 -> 13769 | E22: =IFERROR(ROUND((C22-B22)/B22*100,1),0) -> 1.3
A23: Operations | B23: =SUMIFS(Budget_Data!C2:C49,Budget_Data!B2:B49,A23) -> 1558179 | C23: =SUMIFS(Budget_Data!D2:D49,Budget_Data!B2:B49,A23) -> 1587666 | D23: =C23-B23 -> 29487 | E23: =IFERROR(ROUND((C23-B23)/B23*100,1),0) -> 1.9
A24: R&D | B24: =SUMIFS(Budget_Data!C2:C49,Budget_Data!B2:B49,A24) -> 1338683 | C24: =SUMIFS(Budget_Data!D2:D49,Budget_Data!B2:B49,A24) -> 1356891 | D24: =C24-B24 -> 18208 | E24: =IFERROR(ROUND((C24-B24)/B24*100,1),0) -> 1.4
A27: 3. Break-even Analysis (Laptop Pro 15 example)
A28: Metric | B28: Value
A29: Fixed Costs (assumed monthly overhead) | B29: 34857.692
A30: Unit Selling Price | B30: =INDEX(Product_Data!D2:D11,MATCH("Laptop Pro 15",Product_Data!A2:A11,0)) -> 1200
A31: Unit Variable Cost | B31: =INDEX(Product_Data!C2:C11,MATCH("Laptop Pro 15",Product_Data!A2:A11,0)) -> 850
A32: Contribution Margin per Unit | B32: =B30-B31 -> 350
A33: Break-even Units (per month) | B33: =ROUNDUP(B29/B32,0) -> 100
A34: Break-even Revenue (per month) | B34: =B33*B30 -> 120000
A37: 4. Trend Analysis — 3-Month Moving Average & Simple Forecast
A38: Month | B38: Actual Revenue | C38: 3-Month Moving Avg | D38: Trend (SLOPE-based)
A39: =A5 -> Jan-2025 | B39: =B5 -> 29771
A40: =A6 -> Feb-2025 | B40: =B6 -> 33061
A41: =A7 -> Mar-2025 | B41: =B7 -> 61462 | C41: =AVERAGE(B39:B41) -> 41431.333
A42: =A8 -> Apr-2025 | B42: =B8 -> 26088 | C42: =AVERAGE(B40:B42) -> 40203.667
A43: =A9 -> May-2025 | B43: =B9 -> 45155 | C43: =AVERAGE(B41:B43) -> 44235
A44: =A10 -> Jun-2025 | B44: =B10 -> 62980 | C44: =AVERAGE(B42:B44) -> 44741
A45: =A11 -> Jul-2025 | B45: =B11 -> 93004 | C45: =AVERAGE(B43:B45) -> 67046.333
A46: =A12 -> Aug-2025 | B46: =B12 -> 36426 | C46: =AVERAGE(B44:B46) -> 64136.667
A47: =A13 -> Sep-2025 | B47: =B13 -> 43734 | C47: =AVERAGE(B45:B47) -> 57721.333
...

Sheet Advanced_Functions
A1: ADVANCED EXCEL FUNCTIONS — live demos, all formula-driven off Sales_Data / Product_Data / Customer_Data
A3: 1. XLOOKUP — look up Unit Cost & Margin for a Product
A4: Product (type any) | B4: Unit Cost | C4: Margin %
A5: Laptop Pro 15 | B5: =SUMIF(SalesData[[#All],[Product]],"Laptop Pro 15",Sales_Data!J2:J301) -> 53624
A7: 2. INDEX + MATCH — same lookup, classic method
A8: Product (type any) | B8: Unit Price (INDEX-MATCH)
A9: 4K Monitor | B9: =INDEX(Product_Data!D2:D11,MATCH(A9,Product_Data!A2:A11,0)) -> 420
A11: 3. SUMIFS / COUNTIFS / AVERAGEIFS — Region + Category filtered
A12: Region | B12: Category | C12: Total Revenue | D12: Order Count | E12: Avg Order Value
A13: Europe | B13: Electronics | C13: =IF(A1="","",IF(A1<50,"Low",IF(A1<100,"Medium","High"))) -> High | D13: =IF(A1="","",IF(A1<50,"Low",IF(A1<100,"Medium","High"))) -> High | E13: =IF(A1="","",IF(A1<50,"Low",IF(A1<100,"Medium","High"))) -> High
A15: 4. UNIQUE + SORT — distinct product list, sorted | D15: 5. FILTER — orders with Revenue > $5,000
A16: Unique Products (auto-spills down) | D16: High-Value Orders (auto-spills)
A17: Mine is Excel 2013 No Sort/Filter tools for this example. | D17: Mine is Excel 2013 No Sort/Filter tools for this example.
A40: NOTE: XLOOKUP, UNIQUE, SORT and FILTER are Excel 365 / Excel 2021 dynamic-array functions. If any of these show a Name-Not-Recognized error on your machine, your Excel version/build doesn't yet support them — use the INDEX-MATCH version in Section 2 instead, which works in every Excel version.
A44: 6. IFS — multi-condition rating (no nested IF needed)
A45: Revenue Amount | B45: Performance Rating (IFS)
A46: 75000 | B46: =IF(A1="","",IF(A1<50,"Low",IF(A1<100,"Medium","High"))) -> High
A48: 7. SWITCH — map a code to a label
A49: Region Code | B49: Region Name (SWITCH)
A50: NA | B50: =IF(A1=1,"North",IF(A1=2,"South",IF(A1=3,"East",IF(A1=4,"West","Other")))) -> Other
A52: 8. TEXTJOIN — combine multiple cells with a separator
A53: Region | B53: Category | C53: Product | D53: Combined Label (TEXTJOIN)
A54: Europe | B54: Electronics | C54: 4K Monitor | D54: Use Excel 2013 Sort/Filter tools for this example.
A56: 9. SORTBY — sort one range by another (Products sorted by Margin %, desc)
A57: Products sorted by Margin % (auto-spills)
A58: Use Excel 2013 Sort/Filter tools for this example.
A61: NOTE: IFS, SWITCH, TEXTJOIN and SORTBY are Excel 2019/365 functions. Same compatibility note as Section 4/5 above applies if your Excel build is older.

Sheet slicer
A6: Row Labels | B6: Sum of Revenue
A7: Asia | B7: 76580
A8: Europe | B8: 119725
A9: North America | B9: 70790
A10: South America | B10: 88670
A11: Grand Total | B11: 355765

Sheet Sales_Data
A1: OrderID | B1: Date | C1: Region | D1: Category | E1: Product | F1: CustomerID | G1: SalesRep | H1: Quantity | I1: UnitPrice | J1: Revenue | K1: COGS | L1: GrossProfit
A2: 8001 | B2: 2025-08-03 | C2: Europe | D2: Furniture | E2: Bookshelf Unit | F2: CUST-0019 | G2: Lucas Tanaka | H2: 12 | I2: 190 | J2: 2280 | K2: 1080 | L2: 1200
A3: 8002 | B3: 2025-09-20 | C3: Europe | D3: Stationery | E3: Notebook Pack | F3: CUST-0012 | G3: Noah Kim | H3: 13 | I3: 9 | J3: 117 | K3: 39 | L3: 78
A4: 8003 | B4: 2025-10-27 | C4: North America | D4: Electronics | E4: Laptop Pro 15 | F4: CUST-0028 | G4: Liam Novak | H4: 6 | I4: 1200 | J4: 7200 | K4: 5100 | L4: 2100
A5: 8004 | B5: 2025-04-30 | C5: Europe | D5: Furniture | E5: Standing Desk | F5: CUST-0003 | G5: Ava Müller | H5: 15 | I5: 380 | J5: 5700 | K5: 2700 | L5: 3000
A6: 8005 | B6: 2025-01-18 | C6: South America | D6: Furniture | E6: Filing Cabinet | F6: CUST-0022 | G6: Lucas Tanaka | H6: 8 | I6: 160 | J6: 1280 | K6: 560 | L6: 720
A7: 8006 | B7: 2025-03-21 | C7: North America | D7: Electronics | E7: Ergo Keyboard | F7: CUST-0006 | G7: Liam Novak | H7: 1 | I7: 75 | J7: 75 | K7: 30 | L7: 45
A8: 8007 | B8: 2025-10-10 | C8: North America | D8: Stationery | E8: Notebook Pack | F8: CUST-0022 | G8: Ava Müller | H8: 3 | I8: 9 | J8: 27 | K8: 9 | L8: 18
A9: 8008 | B9: 2025-12-07 | C9: South America | D9: Furniture | E9: Office Chair Deluxe | F9: CUST-0003 | G9: Lucas Tanaka | H9: 3 | I9: 140 | J9: 420 | K9: 195 | L9: 225
A10: 8009 | B10: 2025-04-12 | C10: Europe | D10: Electronics | E10: Wireless Mouse | F10: CUST-0014 | G10: Liam Novak | H10: 13 | I10: 25 | J10: 325 | K10: 104 | L10: 221
A11: 8010 | B11: 2025-10-14 | C11: North America | D11: Stationery | E11: Premium Pen Set | F11: CUST-0025 | G11: Noah Kim | H11: 8 | I11: 15 | J11: 120 | K11: 40 | L11: 80
A12: 8011 | B12: 2025-10-02 | C12: Asia | D12: Furniture | E12: Office Chair Deluxe | F12: CUST-0027 | G12: Olivia Dubois | H12: 15 | I12: 140 | J12: 2100 | K12: 975 | L12: 1125
A13: 8012 | B13: 2025-07-17 | C13: Asia | D13: Stationery | E13: Notebook Pack | F13: CUST-0021 | G13: Lucas Tanaka | H13: 9 | I13: 9 | J13: 81 | K13: 27 | L13: 54
... A301: 8300 | B301: 2025-05-18 | C301: North America | D301: Electronics | E301: 4K Monitor | F301: CUST-0023 | G301: Liam Novak | H301: 15 | I301: 420 | J301: 6300 | K301: 3300 | L301: 3000

Sheet Customer_Data
A1: CustomerID | B1: CustomerName | C1: Segment | D1: Region | E1: JoinYear
A2: CUST-0001 | B2: Company 0001 Ltd. | C2: Enterprise | D2: South America | E2: 2024
A3: CUST-0002 | B3: Company 0002 Ltd. | C3: Enterprise | D3: North America | E3: 2021
A4: CUST-0003 | B4: Company 0003 Ltd. | C4: Mid-Market | D4: Europe | E4: 2021
A5: CUST-0004 | B5: Company 0004 Ltd. | C5: Enterprise | D5: Europe | E5: 2022
A6: CUST-0005 | B6: Company 0005 Ltd. | C6: Small Business | D6: North America | E6: 2024
A7: CUST-0006 | B7: Company 0006 Ltd. | C7: Mid-Market | D7: North America | E7: 2020
A8: CUST-0007 | B8: Company 0007 Ltd. | C8: Small Business | D8: North America | E8: 2021
A9: CUST-0008 | B9: Company 0008 Ltd. | C9: Enterprise | D9: North America | E9: 2022
A10: CUST-0009 | B10: Company 0009 Ltd. | C10: Enterprise | D10: North America | E10: 2024
A11: CUST-0010 | B11: Company 0010 Ltd. | C11: Mid-Market | D11: Europe | E11: 2020
A12: CUST-0011 | B12: Company 0011 Ltd. | C12: Mid-Market | D12: Europe | E12: 2021
A13: CUST-0012 | B13: Company 0012 Ltd. | C13: Small Business | D13: South America | E13: 2021
... A41: CUST-0040 | B41: Company 0040 Ltd. | C41: Enterprise | D41: Europe | E41: 2024

Sheet Product_Data
A1: Product | B1: Category | C1: UnitCost | D1: UnitPrice | E1: MarginPct
A2: Laptop Pro 15 | B2: Electronics | C2: 850 | D2: 1200 | E2: 29.2
A3: Wireless Mouse | B3: Electronics | C3: 8 | D3: 25 | E3: 68
A4: Office Chair Deluxe | B4: Furniture | C4: 65 | D4: 140 | E4: 53.6
A5: Standing Desk | B5: Furniture | C5: 180 | D5: 380 | E5: 52.6
A6: 4K Monitor | B6: Electronics | C6: 220 | D6: 420 | E6: 47.6
A7: Ergo Keyboard | B7: Electronics | C7: 30 | D7: 75 | E7: 60
A8: Bookshelf Unit | B8: Furniture | C8: 90 | D8: 190 | E8: 52.6
A9: Notebook Pack | B9: Stationery | C9: 3 | D9: 9 | E9: 66.7
A10: Premium Pen Set | B10: Stationery | C10: 5 | D10: 15 | E10: 66.7
A11: Filing Cabinet | B11: Furniture | C11: 70 | D11: 160 | E11: 56.2

Sheet Budget_Data
A1: Month | B1: Department | C1: Budgeted | D1: Actual
A2: Jan | B2: Sales | C2: 185940 | D2: 159843
A3: Feb | B3: Sales | C3: 173982 | D3: 163223
A4: Mar | B4: Sales | C4: 188827 | D4: 167696
A5: Apr | B5: Sales | C5: 187640 | D5: 178226
A6: May | B6: Sales | C6: 175382 | D6: 168738
A7: Jun | B7: Sales | C7: 175735 | D7: 167731
A8: Jul | B8: Sales | C8: 181126 | D8: 188942
A9: Aug | B9: Sales | C9: 173436 | D9: 179539
A10: Sep | B10: Sales | C10: 172710 | D10: 163893
A11: Oct | B11: Sales | C11: 187767 | D11: 208870
A12: Nov | B12: Sales | C12: 188418 | D12: 193851
A13: Dec | B13: Sales | C13: 181734 | D13: 171365
... A49: Dec | B49: R&D | C49: 111275 | D49: 103048
